<?xml version="1.0"?>
<robot name="two_link_arm">

  <!-- Origin -->
  <link name="base">
    <inertial>
      <origin xyz="0 0 0" rpy="0 0 0"/>
      <mass value="0.001"/>
      <inertia ixx="1e-6" iyy="1e-6" izz="1e-6" ixy="0" ixz="0" iyz="0"/>
    </inertial>
  </link>

  <!-- First axis (joint 1) -->
  <joint name="joint1" type="revolute">
    <parent link="base"/>
    <child link="link1"/>
    <origin xyz="0 0 0" rpy="0 0 0"/>
    <axis xyz="0 0 1"/>
    <!-- NOTE: not sure if we should keep the limits -->
    <limit lower="-3.14" upper="3.14" effort="10" velocity="2"/>
  </joint>

  <!-- Link 1 -->
  <link name="link1">
    <visual>
      <geometry>
        <cylinder radius="0.05" length="1.0"/>
      </geometry>
      <!-- Cylinder oriented along X -->
      <origin xyz="0.5 0 0" rpy="0 1.5708 0"/>
      <material name="white">
        <color rgba="1 1 1 1"/>
      </material>
    </visual>
    <collision>
      <geometry>
        <cylinder radius="0.05" length="1.0"/>
      </geometry>
      <origin xyz="0.5 0 0" rpy="0 1.5708 0"/>
    </collision>
    <inertial>
      <origin xyz="0.5 0 0" rpy="0 0 0"/>
      <mass value="1.0"/>
      <!-- Inertia calculation: along the two perpendicular axes: 1.0 * ((0.05**2)/4 + (0.75**2)/12) = 0.0475 ; along the length: 1.0 * (0.05)**2 / 2 = 0.00125  -->
      <inertia ixx="0.00125" iyy="0.0475" izz="0.0475" ixy="0" ixz="0" iyz="0"/>
    </inertial>
  </link>

  <!-- Second axis (joint 2) -->
  <joint name="joint2" type="revolute">
    <parent link="link1"/>
    <child link="link2"/>
    <!-- placed at the end of link1 -->
    <origin xyz="1.0 0 0" rpy="0 0 0"/>
    <axis xyz="0 0 1"/>
    <!-- NOTE: not sure if we should keep the limits -->
    <limit lower="-3.14" upper="3.14" effort="10" velocity="2"/>
  </joint>

  <!-- Link 2 -->
  <link name="link2">
    <visual>
      <geometry>
        <cylinder radius="0.05" length="1.0"/>
      </geometry>
      <origin xyz="0.5 0 0" rpy="0 1.5708 0"/>
      <material name="white">
        <color rgba="1 1 1 1"/>
      </material>
    </visual>
    <collision>
      <geometry>
        <cylinder radius="0.05" length="1.0"/>
      </geometry>
      <!-- Cylinder oriented along X -->
      <origin xyz="0.5 0 0" rpy="0 1.5708 0"/>
    </collision>
    <inertial>
      <origin xyz="0.5 0 0" rpy="0 0 0"/>
      <mass value="1.0"/>
      <!-- Inertia calculation: along the two perpendicular axes: 1.0 * ((0.05**2)/4 + (0.75**2)/12) = 0.0475 ; along the length: 1.0 * (0.05)**2 / 2 = 0.00125  -->
      <inertia ixx="0.00125" iyy="0.0475" izz="0.0475" ixy="0" ixz="0" iyz="0"/>
    </inertial>
  </link>


  <!-- ADDITION: end-effector -->
  <!-- End-effector joint -->
  <joint name="ee_joint" type="fixed">
    <parent link="link2"/>
    <child link="ee_link"/>
    <!-- placed at the end of link2 -->
    <origin xyz="1.0 0 0" rpy="0 0 0"/>
  </joint>

  <!-- End-effector link -->
  <link name="ee_link">
    <!-- no mass, no inertia -->
    <inertial>
      <mass value="0.0"/>
      <inertia ixx="0.0" iyy="0.0" izz="0.0" ixy="0.0" ixz="0.0" iyz="0.0"/>
    </inertial>
    <visual>
      <geometry>
        <sphere radius="0.05"/>
      </geometry>
      <origin xyz="0 0 0" rpy="0 0 0"/>
      <material name="green">
        <color rgba="0 1 0 1"/>
      </material>
    </visual>
  </link>

</robot>
